Failure # 1 (occurred at 2020-12-10_20-26-45)
Traceback (most recent call last):
  File "/home/ziyi/anaconda3/envs/py37smarts/lib/python3.7/site-packages/ray/tune/trial_runner.py", line 471, in _process_trial
    result = self.trial_executor.fetch_result(trial)
  File "/home/ziyi/anaconda3/envs/py37smarts/lib/python3.7/site-packages/ray/tune/ray_trial_executor.py", line 430, in fetch_result
    result = ray.get(trial_future[0], DEFAULT_GET_TIMEOUT)
  File "/home/ziyi/anaconda3/envs/py37smarts/lib/python3.7/site-packages/ray/worker.py", line 1538, in get
    raise value.as_instanceof_cause()
ray.exceptions.RayTaskError: [36mray::PPO.train()[39m (pid=27276, ip=192.168.2.131)
  File "python/ray/_raylet.pyx", line 479, in ray._raylet.execute_task
  File "python/ray/_raylet.pyx", line 432, in ray._raylet.execute_task.function_executor
  File "/home/ziyi/anaconda3/envs/py37smarts/lib/python3.7/site-packages/ray/rllib/agents/trainer.py", line 519, in train
    raise e
  File "/home/ziyi/anaconda3/envs/py37smarts/lib/python3.7/site-packages/ray/rllib/agents/trainer.py", line 508, in train
    result = Trainable.train(self)
  File "/home/ziyi/anaconda3/envs/py37smarts/lib/python3.7/site-packages/ray/tune/trainable.py", line 332, in train
    result = self.step()
  File "/home/ziyi/anaconda3/envs/py37smarts/lib/python3.7/site-packages/ray/rllib/agents/trainer_template.py", line 110, in step
    res = next(self.train_exec_impl)
  File "/home/ziyi/anaconda3/envs/py37smarts/lib/python3.7/site-packages/ray/util/iter.py", line 758, in __next__
    return next(self.built_iterator)
  File "/home/ziyi/anaconda3/envs/py37smarts/lib/python3.7/site-packages/ray/util/iter.py", line 785, in apply_foreach
    for item in it:
  File "/home/ziyi/anaconda3/envs/py37smarts/lib/python3.7/site-packages/ray/util/iter.py", line 785, in apply_foreach
    for item in it:
  File "/home/ziyi/anaconda3/envs/py37smarts/lib/python3.7/site-packages/ray/util/iter.py", line 845, in apply_filter
    for item in it:
  File "/home/ziyi/anaconda3/envs/py37smarts/lib/python3.7/site-packages/ray/util/iter.py", line 845, in apply_filter
    for item in it:
  File "/home/ziyi/anaconda3/envs/py37smarts/lib/python3.7/site-packages/ray/util/iter.py", line 785, in apply_foreach
    for item in it:
  File "/home/ziyi/anaconda3/envs/py37smarts/lib/python3.7/site-packages/ray/util/iter.py", line 785, in apply_foreach
    for item in it:
  File "/home/ziyi/anaconda3/envs/py37smarts/lib/python3.7/site-packages/ray/util/iter.py", line 785, in apply_foreach
    for item in it:
  [Previous line repeated 1 more time]
  File "/home/ziyi/anaconda3/envs/py37smarts/lib/python3.7/site-packages/ray/util/iter.py", line 878, in apply_flatten
    for item in it:
  File "/home/ziyi/anaconda3/envs/py37smarts/lib/python3.7/site-packages/ray/util/iter.py", line 830, in add_wait_hooks
    item = next(it)
  File "/home/ziyi/anaconda3/envs/py37smarts/lib/python3.7/site-packages/ray/util/iter.py", line 785, in apply_foreach
    for item in it:
  File "/home/ziyi/anaconda3/envs/py37smarts/lib/python3.7/site-packages/ray/util/iter.py", line 785, in apply_foreach
    for item in it:
  File "/home/ziyi/anaconda3/envs/py37smarts/lib/python3.7/site-packages/ray/util/iter.py", line 785, in apply_foreach
    for item in it:
  [Previous line repeated 1 more time]
  File "/home/ziyi/anaconda3/envs/py37smarts/lib/python3.7/site-packages/ray/util/iter.py", line 472, in base_iterator
    yield ray.get(futures, timeout=timeout)
ray.exceptions.RayTaskError: [36mray::RolloutWorker.par_iter_next()[39m (pid=27283, ip=192.168.2.131)
  File "/home/ziyi/anaconda3/envs/py37smarts/lib/python3.7/site-packages/direct/showbase/ShowBase.py", line 338, in __init__
    self.openDefaultWindow(startDirect = False, props=props)
  File "/home/ziyi/anaconda3/envs/py37smarts/lib/python3.7/site-packages/direct/showbase/ShowBase.py", line 1020, in openDefaultWindow
    self.openMainWindow(*args, **kw)
  File "/home/ziyi/anaconda3/envs/py37smarts/lib/python3.7/site-packages/direct/showbase/ShowBase.py", line 1055, in openMainWindow
    self.openWindow(*args, **kw)
  File "/home/ziyi/anaconda3/envs/py37smarts/lib/python3.7/site-packages/direct/showbase/ShowBase.py", line 800, in openWindow
    raise Exception('Could not open window.')
Exception: Could not open window.

The above exception was the direct cause of the following exception:

[36mray::RolloutWorker.par_iter_next()[39m (pid=27283, ip=192.168.2.131)
  File "python/ray/_raylet.pyx", line 474, in ray._raylet.execute_task
  File "python/ray/_raylet.pyx", line 478, in ray._raylet.execute_task
  File "python/ray/_raylet.pyx", line 479, in ray._raylet.execute_task
  File "python/ray/_raylet.pyx", line 432, in ray._raylet.execute_task.function_executor
  File "/home/ziyi/anaconda3/envs/py37smarts/lib/python3.7/site-packages/ray/util/iter.py", line 1156, in par_iter_next
    return next(self.local_it)
  File "/home/ziyi/anaconda3/envs/py37smarts/lib/python3.7/site-packages/ray/rllib/evaluation/rollout_worker.py", line 281, in gen_rollouts
    yield self.sample()
  File "/home/ziyi/anaconda3/envs/py37smarts/lib/python3.7/site-packages/ray/rllib/evaluation/rollout_worker.py", line 563, in sample
    batches = [self.input_reader.next()]
  File "/home/ziyi/anaconda3/envs/py37smarts/lib/python3.7/site-packages/ray/rllib/evaluation/sampler.py", line 71, in next
    batches = [self.get_data()]
  File "/home/ziyi/anaconda3/envs/py37smarts/lib/python3.7/site-packages/ray/rllib/evaluation/sampler.py", line 181, in get_data
    item = next(self.rollout_provider)
  File "/home/ziyi/anaconda3/envs/py37smarts/lib/python3.7/site-packages/ray/rllib/evaluation/sampler.py", line 505, in _env_runner
    base_env.poll()
  File "/home/ziyi/anaconda3/envs/py37smarts/lib/python3.7/site-packages/ray/rllib/env/base_env.py", line 389, in poll
    obs[i], rewards[i], dones[i], infos[i] = env_state.poll()
  File "/home/ziyi/anaconda3/envs/py37smarts/lib/python3.7/site-packages/ray/rllib/env/base_env.py", line 441, in poll
    self.reset()
  File "/home/ziyi/anaconda3/envs/py37smarts/lib/python3.7/site-packages/ray/rllib/env/base_env.py", line 459, in reset
    self.last_obs = self.env.reset()
  File "/home/ziyi/PSRO-SMARTS/SMARTS/benchmark/wrappers/rllib/simple.py", line 33, in reset
    obs = self.env.reset()
  File "/home/ziyi/PSRO-SMARTS/SMARTS/smarts/env/rllib_hiway_env.py", line 155, in reset
    self._smarts = self._build_smarts()
  File "/home/ziyi/PSRO-SMARTS/SMARTS/smarts/env/rllib_hiway_env.py", line 194, in _build_smarts
    timestep_sec=self._timestep_sec,
  File "/home/ziyi/PSRO-SMARTS/SMARTS/smarts/core/smarts.py", line 104, in __init__
    ) from e
Exception: Display is not found. Try running with different configurations of `export Display=` using `:0`, `:1`... If this does not work please consult the documentation.

